Workbook
Name _ftn1: 'All-in-1-sheet'!#REF!
Name _ftn1: 'BET-S(5)LCE'!#REF!
Name _ftn2: 'All-in-1-sheet'!#REF!
Name _ftn2: 'BET-S(5)LCE'!#REF!
Name _ftn3: 'All-in-1-sheet'!#REF!
Name _ftn3: 'BET-S(5)LCE'!#REF!
Name _ftnref1: 'All-in-1-sheet'!$A$93
Name _ftnref1: 'BET-S(5)LCE'!$A$94
Name _ftnref2: 'All-in-1-sheet'!$A$72
Name _ftnref2: 'BET-S(5)LCE'!$A$73
Name _ftnref3: 'All-in-1-sheet'!#REF!
Name _ftnref3: 'BET-S(5)LCE'!#REF!

Sheet All-in-1-sheet
A1: input
A4: BET-S (Hub Only) | E4: BET-C (Depot Slow & Hub Fast) | I4: Diesel Trucks (Depot&Hub)
A6: Assumptions | E6: Assumptions | I6: Assumptions
A7: 1. A truck discussed in this model is a heavy-duty vehicle consists of a 6×2 tractor unit. 2. BET fuel economy is assumed to have 0.5% decreasing for BET-S because of better management and maintenance. 3. All future cash flows and amortised costs are assumed to pay at the end of each year when accounting for discounted values. | E7: 1. A truck discussed in this model is a heavy-duty vehicle consists of a 6×2 tractor unit. 2. BET fuel economy is assumed to increase every year at 1.4%. 3. All future cash flows and amortised costs are assumed to pay at the end of each year when accounting for discounted values. | I7: 1. A truck discussed in this model is a heavy duty vehicle consists of a 6×2 tractor unit. 2. The fuel economy is assumed to increase every year at 1.1%. 3. All future cash flows and amortised costs are assumed to pay at the end of each year when accounting for discounted values.
A8: Parameter | B8: Units | C8: Public Available Value | E8: Parameter | F8: Units | G8: Public Available Value | I8: Parameter | J8: Units | K8: Public Available Value
A9: Truck specifications | E9: Truck specifications | I9: Truck specifications
A10: Electric Glider Price | B10: £ | C10: 130000 | E10: Electric Glider Price | F10: £ | G10: =C10 -> 130000
A11: Battery modules per truck | B11: modules/truck | C11: 3 | E11: Total battery capacity | F11: kWh | G11: 513 | I11: Diesel truck CAPEX | J11: £ | K11: 144900
A12: Glider Fixed depreciation rate | B12: - | C12: 0.075 | E12: Initial battery price | F12: £/kWh | G12: =C29 -> 148 | I12: Fixed depreciation rate | J12: - | K12: =C12 -> 0.075
A13: Variable glider dipreciation per km | B13: £ | C13: 0.095 | E13: Electric truck CAPEX | F13: £ | G13: =G10+G11*G12 -> 205924 | I13: Variable depreciation per km | J13: £ | K13: =C13 -> 0.095
A14: Glider residual percentage | B14: - | C14: 0.2 | E14: Glider Fixed depreciation rate | F14: - | G14: =C12 -> 0.075 | I14: Truck lifetime | J14: years | K14: =C15 -> 15
A15: Glider lifetime | B15: years | C15: 15 | E15: Variable glider dipreciation per km | F15: £ | G15: =C13 -> 0.095 | I15: Cost of Capital | J15: - | K15: =C16 -> 0.125
A16: Cost of Capital | B16: - | C16: 0.125 | E16: Glider residual value percentage | F16: - | G16: =C14 -> 0.2 | I16: Upfront payment percentage | J16: - | K16: =C17 -> 0.3
A17: Upfront payment percentage | B17: - | C17: 0.3 | E17: Glider lifetime | F17: years | G17: =C15 -> 15 | I17: Loan Term | J17: years | K17: =C18 -> 5
A18: Loan Term | B18: years | C18: 5 | E18: Cost of Capital | F18: - | G18: =C16 -> 0.125 | I18: Loan Amount | J18: £ | K18: =K11*(1-K16) -> 101430
A19: Loan Amount | B19: £ | C19: =C10*(1-C17) -> 91000 | E19: Upfront payment percentage | F19: - | G19: =C17 -> 0.3 | I19: Upfront payment | J19: £ | K19: =K11*K16 -> 43470
A20: Upfront payment | B20: £ | C20: =C10*C17 -> 39000 | E20: Loan Term | F20: years | G20: =C18 -> 5 | I20: Interest payment per year | J20: £ | K20: =K11*(1-K16)*K15 -> 12678.75
A21: Interest payment per year | B21: £ | C21: =C10*(1-C17)*C16 -> 11375 | E21: Loan Amount | F21: £ | G21: =G13*(1-G19) -> 144146.8 | I21: Annual payment | J21: £ | K21: =-PMT(12.5%,5,K18) -> 28487.025
A22: Annual payment | B22: £ | C22: =-PMT(12.5%,5,C19) -> 25557.718 | E22: Upfront payment | F22: £ | G22: =G13*G19 -> 61777.2 | I22: Truck Total Costs NPV | J22: £ | K22: =K21*SUM(K98:K102)+K19 -> 151458.24
A23: Glider Total Costs NPV | B23: £ | C23: =C22*SUM(C98:C102)+C20 -> 135883.86 | E23: Interest payment per year | F23: £ | G23: =G13*(1-G19)*G18 -> 18018.35
E24: Annual payment | F24: £ | G24: =-PMT(12.5%,5,G21) -> 40484.211
E25: Truck Total Costs NPV | F25: £ | G25: =G24*SUM(G98:G102)+G22 -> 215244.21
A27: Battery specifications | E27: Battery specifications
A28: Battery pack capacity | B28: kWh | C28: 171 | E28: Battery residual percentage | F28: - | G28: =C30 -> 0.1
A29: Initial battery price | B29: £/kWh | C29: 148 | E29: Battery Lifetime cycle | F29: - | G29: =C31 -> 2200
A30: Battery residual percentage | B30: - | C30: 0.1 | E30: Battery lifetime | F30: years | G30: =G29/G44 -> 7.5342466
A31: Battery lifetime cycle | B31: cycles | C31: 2200
A32: Battery lifetime | B32: years | C32: =C31/C44 -> 7.5342466
A34: Truck Fixed Annual Operation Costs | E34: Truck Fixed Annual Operation Costs | I34: Truck Fixed Annual Operation Costs
A35: Annual service cost | B35: £/year | C35: 4200 | E35: Annual service cost | F35: £/year | G35: =C35 -> 4200 | I35: Annual service cost | J35: £/year | K35: 4800
A36: Diesel truck consistant Insurance | B36: £ | C36: ='Diesel(5)LCE'!C27 -> 10000 | E36: Diesel truck consistant Insurance | F36: £ | G36: =C36 -> 10000 | I36: Consistent Insurance | J36: £ | K36: 10000
A37: Insurance percentage on top of diesel truck | B37: - | C37: 0.2 | E37: Insurance percentage on top of diesel truck | F37: - | G37: =C37 -> 0.2 | I37: Driver costs per truck | J37: £ | K37: =K161*K45 -> 41469.84
A38: BET insurance | B38: £ | C38: =C36*(1+C37) -> 12000 | E38: BET insurance | F38: £ | G38: =G36*(1+G37) -> 12000
A39: Driver costs per truck | B39: £/year | C39: =C186*C45 -> 41469.84 | E39: Driver costs per truck | F39: £/year | G39: =G161*G45 -> 41469.84
A41: Truck Operarion Details | E41: Truck Operations Details | I41: Truck operations
A42: Daily distance driven with cargo per shift | B42: km | C42: 240 | E42: Daily distance driven with cargo per shift | F42: km | G42: =C42 -> 240 | I42: Daily distance driven with cargo per shift | J42: km | K42: =C42 -> 240
A43: Daily unladen distance driven per shift | B43: km | C43: =C42/7*3 -> 102.85714 | E43: Daily unladen distance driven per shift | F43: km | G43: =G42/7*3 -> 102.85714 | I43: Daily unladen distance driven per shift | J43: km | K43: =K42/7*3 -> 102.85714
A44: Operational days per year | B44: days | C44: 292 | E44: Operational days per year | F44: days | G44: =C44 -> 292 | I44: Operational days per year | J44: days | K44: =C44 -> 292
A45: Shift per day | B45: - | C45: 1 | E45: Shift per day | F45: - | G45: =C45 -> 1 | I45: Shift per day | J45: - | K45: =C45 -> 1
A46: Swaps per day | B46: swaps/day | C46: =MAX(1,(ROUNDUP(((C42+C43)*C45)/(C28*C11/C50),0))) -> 1 | E46: Charges per day | F46: Charges/day | G46: =MAX(1,(ROUNDUP(((G42+G43)*G45)/(G11/G50),0))) -> 1
...

Sheet BET-S(5)LCE
A1: BET-S (Hub Only)
A3: Assumptions
A4: 1. A truck discussed in this model is a heavy-duty vehicle consists of a 6×2 tractor unit. 2. BET fuel economy is assumed to have 0.5% decreasing for BET-S because of better management and maintenance. 3. All future cash flows and amortised costs are assumed to pay at the end of each year when accounting for discounted values.
A5: Parameter | B5: Units | C5: Public Available Value | D5: Source | E5: Notes from Aegis | F5: Notes for public available data
A6: Truck specifications
A7: Electric Glider Price | B7: £ | C7: 130000 | D7: from Iveco
A8: Battery modules per truck | B8: modules/truck | C8: 3 | D8: (Qijiswap, 2025) (NewsQQ, 2024)
A9: Glider Fixed depreciation rate | B9: - | C9: 0.075 | D9: ICCT & …
A10: Variable glider dipreciation per km | B10: £ | C10: 0.095 | F10: Calibrated
A11: Glider residual percentage | B11: - | C11: 0.2 | D11: Aegis management assumption | E11: to align with Octopus numbers | F11: to align with Octopus numbers
A12: Glider lifetime | B12: years | C12: 15 | D12: Aegis management assumption | E12: based on "million mile" warranty claims in market 1 mile = c1.6 km => 15 years | F12: based on "million mile" warranty claims in market 1 mile = c1.6 km => 15 years
A13: Cost of Capital | B13: - | C13: 0.125
A14: Upfront payment percentage | B14: - | C14: 0.3
A15: Loan Term | B15: years | C15: 5
A16: Loan Amount | B16: £ | C16: =C7*(1-C14) -> 91000
A17: Upfront payment | B17: £ | C17: =C7*C14 -> 39000
A18: Interest payment per year | B18: £ | C18: =C7*(1-C14)*C13 -> 11375
A19: Annual payment | B19: £ | C19: =-PMT(C13,5,C16) -> 25557.718
A20: Glider Total Costs NPV | B20: £ | C20: =C19*SUM(C103:C107)+C17 -> 135883.86
A21: Electric glider acquisition cost - changes by 2030 | C21: 0.06
A22: Electric glider acquisition cost - changes by 2040 | C22: 0.03
A23: Glider weight | B23: kg | C23: 9986
A24: Glider Production Emission Factor | B24: kg CO2e/kg | C24: 7
A25: Glider Recycle Emission Saving | B25: - | C25: 0.17
A27: Battery specifications
A28: Battery pack capacity | B28: kWh | C28: 171 | D28: (Qijiswap, 2025) (NewsQQ, 2024)
A29: Initial battery price | B29: £/kWh | C29: 148 | D29: CATL provided quote | E29: Used in Aegis model - adjusted for exchange rate of CNY/GBP of 9.65 (CNY 1,430) | F29: Used in Aegis model - adjusted for exchange rate of CNY/GBP of 9.65 (CNY 1,430)
A30: Battery residual percentage | B30: - | C30: 0.1 | D30: Provided by Brunp | F30: Collected from Brunp consultation
A31: Battery lifetime cycle | B31: cycles | C31: 2200 | D31: ICCT,2021;ICCT,2021EU; ICCT2024 | F31: 2000/1500/3000
A32: Battery lifetime | B32: years | C32: =C31/C48 -> 7.5342466
A33: Battery Production Emission Factor | B33: kg CO2e/kWh | C33: 57
A34: Battery Recycle Emission Saving | B34: - | C34: 0.19
A35: Battery Second Life Capacity | B35: kWh | C35: =C28*0.8 -> 136.8
A36: Battery Sets Needed | B36: - | C36: 2
A38: Truck Fixed Annual Operation Costs
A39: Annual service cost | B39: £/year | C39: 4200 | D39: Same as BET-C
A40: Diesel truck consistant Insurance | B40: £ | C40: ='Diesel(5)LCE'!C27 -> 10000 | D40: (The electric car scheme, 2026) | F40: Electric car insurance through traditional channels costs 15-25% more than petrol equivalents in 2026.
A41: Insurance percentage on top of diesel truck | B41: - | C41: 0.2
A42: BET insurance | B42: £ | C42: =C40*(1+C41) -> 12000
A43: Driver costs per truck | B43: £/year | C43: =C205*C49 -> 41469.84
...

Sheet BET-C(5)LCE
A1: BET-C (Depot Slow & Hub Fast)
A3: Assumptions
A4: 1. A truck discussed in this model is a heavy-duty vehicle consists of a 6×2 tractor unit. 2. BET fuel economy is assumed to increase every year at 1.4%. 3. All future cash flows and amortised costs are assumed to pay at the end of each year when accounting for discounted values.
A5: Parameter | B5: Units | C5: Public Available Value | D5: Source | E5: Notes from Aegis | F5: Notes for public available data
A6: Truck specifications
A7: Electric Glider Price | B7: £ | C7: 130000 | D7: from Iveco
A8: Total battery capacity | B8: kWh | C8: 513 | D8: (Daimler, 2026)
A9: Initial battery price | B9: £/kWh | C9: 148 | D9: CATL provided quote | E9: Used in Aegis model - adjusted for exchange rate of CNY/GBP of 9.65 (CNY 1,430) | F9: Used in Aegis model - adjusted for exchange rate of CNY/GBP of 9.65 (CNY 1,430)
A10: Electric truck CAPEX | B10: £ | C10: =C7+C8*C9 -> 205924 | E10: Based on Rogers's (MAN Trucks) quotes across a range of vehicle sizes
A11: Glider Fixed depreciation rate | B11: - | C11: 0.075
A12: Variable glider dipreciation per km | B12: £ | C12: 0.095
A13: Glider residual value (EOL) ratio | B13: - | C13: 0.2 | D13: Aegis management assumption | E13: to align with Octopus numbers | F13: to align with Octopus numbers
A14: Glider lifetime | B14: years | C14: 15 | D14: Aegis management assumption | E14: pegged to battery life, which is extended due to less battery cycling overall
A15: Cost of Capital | B15: - | C15: 0.125
A16: Upfront payment percentage | B16: - | C16: 0.3
A17: Loan Term | B17: years | C17: 5
A18: Loan Amount | B18: £ | C18: =C10*(1-C16) -> 144146.8
A19: Upfront payment | B19: £ | C19: =C10*C16 -> 61777.2
A20: Interest payment per year | B20: £ | C20: =C10*(1-C16)*C15 -> 18018.35
A21: Annual payment | B21: £ | C21: =-PMT(C15,5,C18) -> 40484.211
A22: Truck Total Costs NPV | B22: £ | C22: =C21*SUM(C97:C101)+C19 -> 215244.21
A23: Glider weight | B23: kg | C23: 9986
A24: Glider Production Emission Factor | B24: kg CO2e/kg | C24: 7
A25: Glider Recycle Emission Saving | B25: - | C25: 0.17
A27: Battery specifications
A28: Battery residual percentage | B28: - | C28: 0.1 | D28: Provided by Brunp | F28: Collected from Brunp consultation
A29: Battery Lifetime cycle | B29: - | C29: 2200
A30: Battery lifetime | B30: years | C30: =C29/C45 -> 7.5342466
A31: Battery Production Emission Factor | B31: kg CO2e/kWh | C31: 57
A32: Battery Recycle Emission Saving | B32: - | C32: 0.05
A33: Battery Sets Needed | B33: - | C33: 2
A35: Truck Fixed Annual Operation Costs
A36: Annual service cost | B36: £/year | C36: 4200 | D36: Same as BET-C
A37: Diesel truck consistant Insurance | B37: £ | C37: 10000
A38: Insurance percentage on top of diesel truck | B38: - | C38: 0.2
A39: BET insurance | B39: £ | C39: =C37*(1+C38) -> 12000
A40: Driver costs per truck | B40: £/year | C40: =C175*C46 -> 41469.84
A42: Truck Operations Details
A43: Daily distance driven with cargo per shift | B43: km | C43: 240 | E43: derived in model, but used as starting basis here
A44: Daily unladen distance driven per shift | B44: km | C44: =C43/7*3 -> 102.85714 | D44: (DfT, 2024) | F44: The ratio of full-loaded and unladen driven distance is 7:3 in the UK
...

Sheet Diesel(5)LCE
A1: Diesel Trucks (Depot&Hub)
A3: Assumptions
A4: 1. A truck discussed in this model is a heavy duty vehicle consists of a 6×2 tractor unit. 2. The fuel economy is assumed to increase every year at 1.1%. 3. All future cash flows and amortised costs are assumed to pay at the end of each year when accounting for discounted values.
A5: Parameter | B5: Units | C5: Public Available Value | D5: Source | E5: Notes from Aegis | F5: Notes for public available data
A6: Truck specifications
A8: Diesel truck CAPEX | B8: £ | C8: 144900 | F8: Average price of 5 models
A9: Fixed depreciation rate | B9: - | C9: 0.075
A10: Variable depreciation per km | B10: £ | C10: 0.095
A11: Truck lifetime | B11: years | C11: 15 | D11: Aegis management assumption
A12: Cost of Capital | B12: - | C12: 0.125
A13: Upfront payment percentage | B13: - | C13: 0.3
A14: Loan Term | B14: years | C14: 5
A15: Loan Amount | B15: £ | C15: =C8*(1-C13) -> 101430
A16: Upfront payment | B16: £ | C16: =C8*C13 -> 43470
A17: Interest payment per year | B17: £ | C17: =C8*(1-C13)*C12 -> 12678.75
A18: Annual payment | B18: £ | C18: =-PMT(C12,5,C15) -> 28487.025
A19: Truck Total Costs NPV | B19: £ | C19: =C18*SUM(C102:C106)+C16 -> 151458.24
A20: Truck Curb Weight | B20: kg | C20: 11022
A21: Truck Production Emission Factor | B21: kg CO2e/kg | C21: 7
A22: Diesel Truck Recycle Emission Saving | B22: - | C22: 0.17
A23: Truck Life Cycle Considered Lifetime | B23: years | C23: 10
A25: Truck Fixed Annual Operation Costs
A26: Annual service cost | B26: £/year | C26: 4800 | D26: Aegis management assumption | E26: aligned to Octopus model of £400 per month
A27: Consistent Insurance | B27: £ | C27: 10000 | D27: (Nimblefins, 2026) (Switcha, 2025) | F27: As of January 2026, the average cost to insure a single HGV typically ranges from £5,000 to £10,000 per year. Taking the highest number to represent the large truck model.
A28: Driver costs per truck | B28: £ | C28: =C178*C35 -> 41469.84
A31: Truck operations
A32: Daily distance driven - Full Loaded | B32: km | C32: 240 | E32: derived in model, but used as starting basis here
A33: Daily unladen distance driven | B33: km | C33: =C32/7*3 -> 102.85714 | D33: (DfT, 2024)
A34: Operational days per year | B34: days | C34: 292 | D34: Aegis management assumption | E34: 80% utilisation rate of trucks on days in the year basis
A35: Shift per day | B35: - | C35: 1
A36: Refuels per day | B36: Refuel/day | C36: =C35 -> 1 | D36: Aegis management assumption
A37: Truck fuel economy annual increase rate | B37: - | C37: 0.011
A38: Energy save compared to when full-loaded | B38: - | C38: 0.25 | D38: ICCT, 2022 | F38: Unladen trucks are assumed to have this % of energy save compared to when full-loaded.
A39: Depot refuelling percentage | B39: - | C39: 0.8 | D39: Aegis management assumption | E39: based on classic 80:20 split depot:public
A40: Daily diesel use in the first year | B40: l | C40: =C$32*C$35*C50+C$33*C$35*C60 -> 111
A41: Daily diesel use in the second year | B41: l | C41: =C$32*C$35*C51+C$33*C$35*C61 -> 112.221 | E41: assumed energy efficiency decreases over time
A42: Daily diesel use in the third year | B42: l | C42: =C$32*C$35*C52+C$33*C$35*C62 -> 113.45543
A43: Daily diesel use in the fourth year | B43: l | C43: =C$32*C$35*C53+C$33*C$35*C63 -> 114.70344
A44: Daily diesel use in the fifth year | B44: l | C44: =C$32*C$35*C54+C$33*C$35*C64 -> 115.96518
A45: Daily diesel use in the sixth year | B45: l | C45: =C$32*C$35*C55+C$33*C$35*C65 -> 117.2408
...

Sheet Future Dynamic Input
A1: Input future changes
A2: Variable | B2: annual change by 2030 | C2: Reference | D2: annual change by 2040 | E2: Reference
A3: Diesel truck acquisition cost | B3: 0.01 | C3: ICCT, 2021 | D3: 0.005 | E3: Assumed
A4: Electric glider acquisition cost | B4: -0.06 | C4: ICCT, 2024, ICCT, 2021 + ASSUMED | D4: -0.03 | E4: Assumed
A5: Initial battery price | B5: -0.08 | C5: ICCT, 2024, ICCT, 2021 | D5: -0.04 | E5: Assumed
A6: Fuel economy in the purchase year -Full Loaded - Diesel | B6: -0.026 | C6: ICCT, 2021 | D6: -0.013 | E6: Assumed
A7: Fuel economy in the purchase year -Full Loaded - BET-C&BET-S | B7: -0.031 | C7: ICCT, 2021 | D7: -0.015 | E7: Assumed
A8: Battery Lifetime cycle | B8: 200 | C8: ICCT, 2024 | D8: 200 | E8: ICCT, 2024
